[2024-04-02T22:30:22.511+0000] {taskinstance.py:1979} INFO - Dependencies all met for dep_context=non-requeueable deps ti=<TaskInstance: food_pipeline_dag_v03.convert_data manual__2024-04-02T22:30:18.479645+00:00 [queued]>
[2024-04-02T22:30:22.518+0000] {taskinstance.py:1979} INFO - Dependencies all met for dep_context=requeueable deps ti=<TaskInstance: food_pipeline_dag_v03.convert_data manual__2024-04-02T22:30:18.479645+00:00 [queued]>
[2024-04-02T22:30:22.518+0000] {taskinstance.py:2193} INFO - Starting attempt 1 of 1
[2024-04-02T22:30:22.527+0000] {taskinstance.py:2217} INFO - Executing <Task(PythonOperator): convert_data> on 2024-04-02 22:30:18.479645+00:00
[2024-04-02T22:30:22.532+0000] {standard_task_runner.py:60} INFO - Started process 1789 to run task
[2024-04-02T22:30:22.534+0000] {standard_task_runner.py:87} INFO - Running: ['***', 'tasks', 'run', 'food_pipeline_dag_v03', 'convert_data', 'manual__2024-04-02T22:30:18.479645+00:00', '--job-id', '23', '--raw', '--subdir', 'DAGS_FOLDER/food_dag.py', '--cfg-path', '/tmp/tmpfiu82nvg']
[2024-04-02T22:30:22.536+0000] {standard_task_runner.py:88} INFO - Job 23: Subtask convert_data
[2024-04-02T22:30:22.571+0000] {task_command.py:423} INFO - Running <TaskInstance: food_pipeline_dag_v03.convert_data manual__2024-04-02T22:30:18.479645+00:00 [running]> on host 8a5043ba3213
[2024-04-02T22:30:22.627+0000] {taskinstance.py:2513} INFO - Exporting env vars: AIRFLOW_CTX_DAG_OWNER='kenneth' AIRFLOW_CTX_DAG_ID='food_pipeline_dag_v03' AIRFLOW_CTX_TASK_ID='convert_data' AIRFLOW_CTX_EXECUTION_DATE='2024-04-02T22:30:18.479645+00:00' AIRFLOW_CTX_TRY_NUMBER='1' AIRFLOW_CTX_DAG_RUN_ID='manual__2024-04-02T22:30:18.479645+00:00'
[2024-04-02T22:30:22.694+0000] {taskinstance.py:2731} ERROR - Task failed with exception
Traceback (most recent call last):
  File "/home/airflow/.local/lib/python3.8/site-packages/airflow/models/taskinstance.py", line 444, in _execute_task
    result = _execute_callable(context=context, **execute_callable_kwargs)
  File "/home/airflow/.local/lib/python3.8/site-packages/airflow/models/taskinstance.py", line 414, in _execute_callable
    return execute_callable(context=context, **execute_callable_kwargs)
  File "/home/airflow/.local/lib/python3.8/site-packages/airflow/operators/python.py", line 200, in execute
    return_value = self.execute_callable()
  File "/home/airflow/.local/lib/python3.8/site-packages/airflow/operators/python.py", line 217, in execute_callable
    return self.python_callable(*self.op_args, **self.op_kwargs)
  File "/opt/airflow/dags/food_dag.py", line 37, in convert_data
    df.to_parquet(parquet_file_path, engine='pyarrow', index=False)
  File "/home/airflow/.local/lib/python3.8/site-packages/pandas/core/frame.py", line 2889, in to_parquet
    return to_parquet(
  File "/home/airflow/.local/lib/python3.8/site-packages/pandas/io/parquet.py", line 411, in to_parquet
    impl.write(
  File "/home/airflow/.local/lib/python3.8/site-packages/pandas/io/parquet.py", line 161, in write
    path_or_handle, handles, kwargs["filesystem"] = _get_path_or_handle(
  File "/home/airflow/.local/lib/python3.8/site-packages/pandas/io/parquet.py", line 110, in _get_path_or_handle
    handles = get_handle(
  File "/home/airflow/.local/lib/python3.8/site-packages/pandas/io/common.py", line 737, in get_handle
    check_parent_directory(str(handle))
  File "/home/airflow/.local/lib/python3.8/site-packages/pandas/io/common.py", line 600, in check_parent_directory
    raise OSError(rf"Cannot save file into a non-existent directory: '{parent}'")
OSError: Cannot save file into a non-existent directory: 'opt/***/data'
[2024-04-02T22:30:22.705+0000] {taskinstance.py:1149} INFO - Marking task as FAILED. dag_id=food_pipeline_dag_v03, task_id=convert_data, execution_date=20240402T223018, start_date=20240402T223022, end_date=20240402T223022
[2024-04-02T22:30:22.714+0000] {standard_task_runner.py:107} ERROR - Failed to execute job 23 for task convert_data (Cannot save file into a non-existent directory: 'opt/***/data'; 1789)
[2024-04-02T22:30:22.748+0000] {local_task_job_runner.py:234} INFO - Task exited with return code 1
[2024-04-02T22:30:22.761+0000] {taskinstance.py:3312} INFO - 0 downstream tasks scheduled from follow-on schedule check
