[2024-04-02T22:16:56.117+0000] {taskinstance.py:1979} INFO - Dependencies all met for dep_context=non-requeueable deps ti=<TaskInstance: food_pipeline_dag_v02.clean_data manual__2024-04-02T22:16:52.938706+00:00 [queued]>
[2024-04-02T22:16:56.123+0000] {taskinstance.py:1979} INFO - Dependencies all met for dep_context=requeueable deps ti=<TaskInstance: food_pipeline_dag_v02.clean_data manual__2024-04-02T22:16:52.938706+00:00 [queued]>
[2024-04-02T22:16:56.123+0000] {taskinstance.py:2193} INFO - Starting attempt 1 of 1
[2024-04-02T22:16:56.133+0000] {taskinstance.py:2217} INFO - Executing <Task(PythonOperator): clean_data> on 2024-04-02 22:16:52.938706+00:00
[2024-04-02T22:16:56.138+0000] {standard_task_runner.py:60} INFO - Started process 1439 to run task
[2024-04-02T22:16:56.141+0000] {standard_task_runner.py:87} INFO - Running: ['***', 'tasks', 'run', 'food_pipeline_dag_v02', 'clean_data', 'manual__2024-04-02T22:16:52.938706+00:00', '--job-id', '18', '--raw', '--subdir', 'DAGS_FOLDER/food_dag.py', '--cfg-path', '/tmp/tmpialemptk']
[2024-04-02T22:16:56.142+0000] {standard_task_runner.py:88} INFO - Job 18: Subtask clean_data
[2024-04-02T22:16:56.179+0000] {task_command.py:423} INFO - Running <TaskInstance: food_pipeline_dag_v02.clean_data manual__2024-04-02T22:16:52.938706+00:00 [running]> on host 8a5043ba3213
[2024-04-02T22:16:56.235+0000] {taskinstance.py:2513} INFO - Exporting env vars: AIRFLOW_CTX_DAG_OWNER='kenneth' AIRFLOW_CTX_DAG_ID='food_pipeline_dag_v02' AIRFLOW_CTX_TASK_ID='clean_data' AIRFLOW_CTX_EXECUTION_DATE='2024-04-02T22:16:52.938706+00:00' AIRFLOW_CTX_TRY_NUMBER='1' AIRFLOW_CTX_DAG_RUN_ID='manual__2024-04-02T22:16:52.938706+00:00'
[2024-04-02T22:16:56.236+0000] {taskinstance.py:2731} ERROR - Task failed with exception
Traceback (most recent call last):
  File "/home/airflow/.local/lib/python3.8/site-packages/airflow/models/taskinstance.py", line 444, in _execute_task
    result = _execute_callable(context=context, **execute_callable_kwargs)
  File "/home/airflow/.local/lib/python3.8/site-packages/airflow/models/taskinstance.py", line 414, in _execute_callable
    return execute_callable(context=context, **execute_callable_kwargs)
  File "/home/airflow/.local/lib/python3.8/site-packages/airflow/operators/python.py", line 200, in execute
    return_value = self.execute_callable()
  File "/home/airflow/.local/lib/python3.8/site-packages/airflow/operators/python.py", line 217, in execute_callable
    return self.python_callable(*self.op_args, **self.op_kwargs)
  File "/opt/airflow/dags/food_dag.py", line 17, in clean_data
    ti = kwargs['ti']
NameError: name 'kwargs' is not defined
[2024-04-02T22:16:56.241+0000] {taskinstance.py:1149} INFO - Marking task as FAILED. dag_id=food_pipeline_dag_v02, task_id=clean_data, execution_date=20240402T221652, start_date=20240402T221656, end_date=20240402T221656
[2024-04-02T22:16:56.249+0000] {standard_task_runner.py:107} ERROR - Failed to execute job 18 for task clean_data (name 'kwargs' is not defined; 1439)
[2024-04-02T22:16:56.274+0000] {local_task_job_runner.py:234} INFO - Task exited with return code 1
[2024-04-02T22:16:56.285+0000] {taskinstance.py:3312} INFO - 0 downstream tasks scheduled from follow-on schedule check
