[2024-04-02T22:11:11.984+0000] {taskinstance.py:1979} INFO - Dependencies all met for dep_context=non-requeueable deps ti=<TaskInstance: food_pipeline_dag_v02.clean_data manual__2024-04-02T22:11:09.216793+00:00 [queued]>
[2024-04-02T22:11:11.990+0000] {taskinstance.py:1979} INFO - Dependencies all met for dep_context=requeueable deps ti=<TaskInstance: food_pipeline_dag_v02.clean_data manual__2024-04-02T22:11:09.216793+00:00 [queued]>
[2024-04-02T22:11:11.990+0000] {taskinstance.py:2193} INFO - Starting attempt 1 of 1
[2024-04-02T22:11:12.002+0000] {taskinstance.py:2217} INFO - Executing <Task(PythonOperator): clean_data> on 2024-04-02 22:11:09.216793+00:00
[2024-04-02T22:11:12.006+0000] {standard_task_runner.py:60} INFO - Started process 1287 to run task
[2024-04-02T22:11:12.008+0000] {standard_task_runner.py:87} INFO - Running: ['***', 'tasks', 'run', 'food_pipeline_dag_v02', 'clean_data', 'manual__2024-04-02T22:11:09.216793+00:00', '--job-id', '16', '--raw', '--subdir', 'DAGS_FOLDER/food_dag.py', '--cfg-path', '/tmp/tmpefm4yt_t']
[2024-04-02T22:11:12.010+0000] {standard_task_runner.py:88} INFO - Job 16: Subtask clean_data
[2024-04-02T22:11:12.041+0000] {task_command.py:423} INFO - Running <TaskInstance: food_pipeline_dag_v02.clean_data manual__2024-04-02T22:11:09.216793+00:00 [running]> on host 8a5043ba3213
[2024-04-02T22:11:12.094+0000] {taskinstance.py:2513} INFO - Exporting env vars: AIRFLOW_CTX_DAG_OWNER='kenneth' AIRFLOW_CTX_DAG_ID='food_pipeline_dag_v02' AIRFLOW_CTX_TASK_ID='clean_data' AIRFLOW_CTX_EXECUTION_DATE='2024-04-02T22:11:09.216793+00:00' AIRFLOW_CTX_TRY_NUMBER='1' AIRFLOW_CTX_DAG_RUN_ID='manual__2024-04-02T22:11:09.216793+00:00'
[2024-04-02T22:11:12.096+0000] {taskinstance.py:2731} ERROR - Task failed with exception
Traceback (most recent call last):
  File "/home/airflow/.local/lib/python3.8/site-packages/airflow/models/taskinstance.py", line 444, in _execute_task
    result = _execute_callable(context=context, **execute_callable_kwargs)
  File "/home/airflow/.local/lib/python3.8/site-packages/airflow/models/taskinstance.py", line 414, in _execute_callable
    return execute_callable(context=context, **execute_callable_kwargs)
  File "/home/airflow/.local/lib/python3.8/site-packages/airflow/operators/python.py", line 200, in execute
    return_value = self.execute_callable()
  File "/home/airflow/.local/lib/python3.8/site-packages/airflow/operators/python.py", line 217, in execute_callable
    return self.python_callable(*self.op_args, **self.op_kwargs)
  File "/opt/airflow/dags/food_dag.py", line 17, in clean_data
    df = pd.read_csv('data.csv')
  File "/home/airflow/.local/lib/python3.8/site-packages/pandas/io/parsers/readers.py", line 912, in read_csv
    return _read(filepath_or_buffer, kwds)
  File "/home/airflow/.local/lib/python3.8/site-packages/pandas/io/parsers/readers.py", line 577, in _read
    parser = TextFileReader(filepath_or_buffer, **kwds)
  File "/home/airflow/.local/lib/python3.8/site-packages/pandas/io/parsers/readers.py", line 1407, in __init__
    self._engine = self._make_engine(f, self.engine)
  File "/home/airflow/.local/lib/python3.8/site-packages/pandas/io/parsers/readers.py", line 1661, in _make_engine
    self.handles = get_handle(
  File "/home/airflow/.local/lib/python3.8/site-packages/pandas/io/common.py", line 859, in get_handle
    handle = open(
FileNotFoundError: [Errno 2] No such file or directory: 'data.csv'
[2024-04-02T22:11:12.103+0000] {taskinstance.py:1149} INFO - Marking task as FAILED. dag_id=food_pipeline_dag_v02, task_id=clean_data, execution_date=20240402T221109, start_date=20240402T221111, end_date=20240402T221112
[2024-04-02T22:11:12.111+0000] {standard_task_runner.py:107} ERROR - Failed to execute job 16 for task clean_data ([Errno 2] No such file or directory: 'data.csv'; 1287)
[2024-04-02T22:11:12.141+0000] {local_task_job_runner.py:234} INFO - Task exited with return code 1
[2024-04-02T22:11:12.160+0000] {taskinstance.py:3312} INFO - 0 downstream tasks scheduled from follow-on schedule check
